Workbook
Name SegmentaciónDeDatos_Barrio: #N/A
Name SegmentaciónDeDatos_Categoria: #N/A

Sheet Hoja1
B2: Categoria | C2: Sub Categoria | D2: Nombre | E2: Localidad | F2: Barrio | G2: Video | H2: Direccion | I2: Link Mapa | J2: Direccion Geo (Power BI) | K2: Visitada | L2: Comentarios
B3: Bodegon | C3: Bodegon | D3: Casa Cuba | E3: CABA | F3: Belgrano | G3: https://www.instagram.com/p/Dcrl0znt4_u/ | H3: Cuba 1877 | I3: https://www.google.com/maps/search/?api=1&query=Casa%20Cuba%2C%20Cuba%201877%2C%20Belgrano%2C%20CABA%2C%20Argentina | J3: Cuba 1877, Belgrano, Ciudad Autonoma de Buenos Aires, Argentina
B4: Bodegon | C4: Bodegon | D4: Burdo | E4: CABA | F4: Colegiales | G4: https://www.instagram.com/p/DccKNw2OHoY/ | H4: Delgado 1199 | I4: https://www.google.com/maps/search/?api=1&query=Burdo%2C%20Delgado%201199%2C%20Colegiales%2C%20CABA%2C%20Argentina | J4: Delgado 1199, Colegiales, Ciudad Autonoma de Buenos Aires, Argentina
B5: Bodegon | C5: Bodegon | D5: La Escuela | E5: CABA | F5: Saavedra | G5: https://www.instagram.com/p/DcJLAs7NTN7/ | H5: Manuela Pedraza 2803 | I5: https://www.google.com/maps/search/?api=1&query=La%20Escuela%2C%20Manuela%20Pedraza%202803%2C%20Saavedra%2C%20CABA%2C%20Argentina | J5: Manuela Pedraza 2803, Saavedra, Ciudad Autonoma de Buenos Aires, Argentina
B6: Bodegon | C6: Bodegon | D6: Cantina Mandia | E6: CABA | F6: Colegiales | G6: https://www.instagram.com/p/DcCPkO3TdK4/ | H6: Zapiola 1218 | I6: https://www.google.com/maps/search/?api=1&query=Cantina%20Mandia%2C%20Zapiola%201218%2C%20Colegiales%2C%20CABA%2C%20Argentina | J6: Zapiola 1218, Colegiales, Ciudad Autonoma de Buenos Aires, Argentina
B7: Bodegon | C7: Bodegon | D7: Somos Asado | E7: CABA | F7: Villa Crespo | G7: https://www.instagram.com/p/Db_vglEp-xj/ | H7: Av. Scalabrini Ortiz 651 | I7: https://www.google.com/maps/search/?api=1&query=Somos%20Asado%2C%20Av.%20Scalabrini%20Ortiz%20651%2C%20Villa%20Crespo%2C%20CABA%2C%20Argentina | J7: Av. Scalabrini Ortiz 651, Villa Crespo, Ciudad Autonoma de Buenos Aires, Argentina
B8: Bodegon | C8: Bodegon | D8: Laserio Cantina | E8: CABA | F8: Devoto | G8: https://www.instagram.com/p/DbrOs5xOxDc/ | H8: Mosconi 3906 | I8: https://www.google.com/maps/search/?api=1&query=Laserio%20Cantina%2C%20Mosconi%203906%2C%20Devoto%2C%20CABA%2C%20Argentina | J8: Mosconi 3906, Devoto, Ciudad Autonoma de Buenos Aires, Argentina
B9: Bodegon | C9: Bodegon | D9: Tinte Atelier de pasta | E9: CABA | F9: Villa Crespo | G9: https://www.instagram.com/p/DatqytBxIVR/ | H9: Castillo 997 | I9: https://www.google.com/maps/search/?api=1&query=Tinte%20Atelier%20de%20pasta%2C%20Castillo%20997%2C%20Villa%20Crespo%2C%20CABA%2C%20Argentina | J9: Castillo 997, Villa Crespo, Ciudad Autonoma de Buenos Aires, Argentina
B10: Bodegon | C10: Bodegon | D10: Rioba | E10: CABA | F10: Palermo | G10: https://www.instagram.com/p/DaRWCBzRStd/ | H10: Costa Rica 4588 | I10: https://www.google.com/maps/search/?api=1&query=Rioba%2C%20Costa%20Rica%204588%2C%20Palermo%2C%20CABA%2C%20Argentina | J10: Costa Rica 4588, Palermo, Ciudad Autonoma de Buenos Aires, Argentina
B11: Bodegon | C11: Bodegon | D11: Ovidio | E11: CABA | F11: Belgrano | G11: https://www.instagram.com/p/DYnaFAQPTBO/ | H11: Jose Hernandez 2345 | I11: https://www.google.com/maps/search/?api=1&query=Ovidio%2C%20Jose%20Hernandez%202345%2C%20Belgrano%2C%20CABA%2C%20Argentina | J11: Jose Hernandez 2345, Belgrano, Ciudad Autonoma de Buenos Aires, Argentina
B12: Bodegon | C12: Bodegon | D12: Rondinella | E12: CABA | F12: Chacarita | G12: https://www.instagram.com/p/DGLib_9Rou4/ | H12: Av. Alvarez thomas 12 | I12: https://www.google.com/maps/search/?api=1&query=Rondinella%2C%20Av.%20Alvarez%20thomas%2012%2C%20Chacarita%2C%20CABA%2C%20Argentina | J12: Av. Alvarez thomas 12, Chacarita, Ciudad Autonoma de Buenos Aires, Argentina
B13: Bodegon | C13: Bodegon | D13: GEVP | E13: CABA | F13: Villa del Parque | G13: https://www.instagram.com/reel/DTStg6GjYtH/ | H13: Tinogaste 3455 | I13: https://www.google.com/maps/search/?api=1&query=GEVP%2C%20Tinogaste%203455%2C%20Villa%20del%20Parque%2C%20CABA%2C%20Argentina | J13: Tinogaste 3455, Villa del Parque, Ciudad Autonoma de Buenos Aires, Argentina
B14: Bodegon | C14: Bodegon | D14: La Tia Ñata | E14: GBA | F14: Tigre | G14: https://www.instagram.com/p/DYKu3q0T0Rj/ | H14: Las Heras 1318, Dique Lujan | I14: https://www.google.com/maps/search/?api=1&query=La%20Tia%20%C3%91ata%2C%20Las%20Heras%201318%2C%20Dique%20Lujan%2C%20Tigre%2C%20Provincia%20de%20Buenos%20Aires%2C%20Argentina | J14: Las Heras 1318, Dique Lujan, Tigre, Provincia de Buenos Aires, Argentina
... B17: Bodegon | C17: Bodegon | D17: The New Brighton | E17: CABA | F17: Retiro | G17: https://www.instagram.com/p/DWXIT32xDqx/ | H17: Sarmiento 645 | I17: https://www.google.com/maps/search/?api=1&query=The%20New%20Brighton%2C%20Sarmiento%20645%2C%20Retiro%2C%20CABA%2C%20Argentina | J17: Sarmiento 645, Retiro, Ciudad Autonoma de Buenos Aires, Argentina
A18: Español | B18: Bodegon | C18: Bodegon | D18: Lalin | E18: CABA | F18: Monserrat | G18: https://www.instagram.com/p/DWVAqVoRcgP/ | H18: Moreno 1949 | I18: https://www.google.com/maps/search/?api=1&query=Lalin%2C%20Moreno%201949%2C%20Monserrat%2C%20CABA%2C%20Argentina | J18: Moreno 1949, Monserrat, Ciudad Autonoma de Buenos Aires, Argentina
B19: Bodegon | C19: Bodegon | D19: Casa Albardon | E19: GBA | F19: Tigre | G19: https://www.instagram.com/p/DV3sSQijbB6/ | H19: Luis Pereyra 2 | I19: https://www.google.com/maps/search/?api=1&query=Casa%20Albardon%2C%20Luis%20Pereyra%202%2C%20Tigre%2C%20Provincia%20de%20Buenos%20Aires%2C%20Argentina | J19: Luis Pereyra 2, Tigre, Provincia de Buenos Aires, Argentina
B20: Bodegon | C20: Bodegon | D20: El bodegon de Benito | E20: CABA | F20: Villa Crespo | G20: https://www.instagram.com/p/DVb0DUriR7s/ | H20: Antezana 340 | I20: https://www.google.com/maps/search/?api=1&query=El%20bodegon%20de%20Benito%2C%20Antezana%20340%2C%20Villa%20Crespo%2C%20CABA%2C%20Argentina | J20: Antezana 340, Villa Crespo, Ciudad Autonoma de Buenos Aires, Argentina
B21: Bodegon | C21: Bodegon | D21: El Desubicado | E21: GBA | F21: Vicente Lopez | G21: https://www.instagram.com/p/DVjxqKelNqx/ | H21: Av. Del Libertador 1031 | I21: https://www.google.com/maps/search/?api=1&query=El%20Desubicado%2C%20Av.%20Del%20Libertador%201031%2C%20Vicente%20Lopez%2C%20Provincia%20de%20Buenos%20Aires%2C%20Argentina | J21: Av. Del Libertador 1031, Vicente Lopez, Provincia de Buenos Aires, Argentina
B22: Bodegon | C22: Bodegon | D22: Club Bar Bodegon (club 25 de mayo) | E22: GBA | F22: Martinez | G22: https://www.instagram.com/p/DVTYCWHDVWU/ | H22: Rodriguez Peña 941 | I22: https://www.google.com/maps/search/?api=1&query=Club%20Bar%20Bodegon%20%28club%2025%20de%20mayo%29%2C%20Rodriguez%20Pe%C3%B1a%20941%2C%20Martinez%2C%20Provincia%20de%20Buenos%20Aires%2C%20Argentina | J22: Rodriguez Peña 941, Martinez, Provincia de Buenos Aires, Argentina
B23: Bodegon | C23: Bodegon | D23: Bodegon Colegiales | E23: CABA | F23: Colegiales | G23: https://www.instagram.com/p/DULTE5EjbNf/ | H23: Virrey Loreto 3520 | I23: https://www.google.com/maps/search/?api=1&query=Bodegon%20Colegiales%2C%20Virrey%20Loreto%203520%2C%20Colegiales%2C%20CABA%2C%20Argentina | J23: Virrey Loreto 3520, Colegiales, Ciudad Autonoma de Buenos Aires, Argentina
B24: Bodegon | C24: Bodegon | D24: Entre Amigos | E24: CABA | F24: Villa Luro | G24: https://www.instagram.com/p/DRpVXwxgNbt/ | H24: Av. Juan B. Justo 8394 | I24: https://www.google.com/maps/search/?api=1&query=Entre%20Amigos%2C%20Av.%20Juan%20B.%20Justo%208394%2C%20Villa%20Luro%2C%20CABA%2C%20Argentina | J24: Av. Juan B. Justo 8394, Villa Luro, Ciudad Autonoma de Buenos Aires, Argentina
B25: Bodegon | C25: Bodegon | D25: La fonda de Artigas | E25: CABA | F25: Agronomia | G25: https://www.instagram.com/p/DUg6SHhDzvB/ | H25: Navarro 2544 | I25: https://www.google.com/maps/search/?api=1&query=La%20fonda%20de%20Artigas%2C%20Navarro%202544%2C%20Agronomia%2C%20CABA%2C%20Argentina | J25: Navarro 2544, Agronomia, Ciudad Autonoma de Buenos Aires, Argentina
B26: Bodegon | C26: Bodegon | D26: La amistad Resto | E26: CABA | F26: Palermo | G26: https://www.instagram.com/p/DUV9JQBknPl/ | H26: Juncal 4500 | I26: https://www.google.com/maps/search/?api=1&query=La%20amistad%20Resto%2C%20Juncal%204500%2C%20Palermo%2C%20CABA%2C%20Argentina | J26: Juncal 4500, Palermo, Ciudad Autonoma de Buenos Aires, Argentina
A27: Pescado | B27: Bodegon | C27: Bodegon | D27: La Pesceria | E27: CABA | F27: Palermo | G27: https://www.instagram.com/p/DTbsnJgkahU/ | H27: Coronel Diaz 1651 | I27: https://www.google.com/maps/search/?api=1&query=La%20Pesceria%2C%20Coronel%20Diaz%201651%2C%20Palermo%2C%20CABA%2C%20Argentina | J27: Coronel Diaz 1651, Palermo, Ciudad Autonoma de Buenos Aires, Argentina
A28: pastas | B28: Bodegon | C28: Bodegon | D28: Pepe Di Roma | E28: CABA | F28: Devoto | G28: https://www.instagram.com/p/DRxqPpRDjRB/ | H28: Av. Francisco Beiró 3701 | I28: https://www.google.com/maps/search/?api=1&query=Pepe%20Di%20Roma%2C%20Av.%20Francisco%20Beir%C3%B3%203701%2C%20Devoto%2C%20CABA%2C%20Argentina | J28: Av. Francisco Beiró 3701, Devoto, Ciudad Autonoma de Buenos Aires, Argentina
B29: Bodegon | C29: Bodegon | D29: Cantina Chichilo | E29: CABA | F29: Paternal | G29: https://www.instagram.com/p/DR0gXNhDpAL/ | H29: Camarones 1901 | I29: https://www.google.com/maps/search/?api=1&query=Cantina%20Chichilo%2C%20Camarones%201901%2C%20Paternal%2C%20CABA%2C%20Argentina | J29: Camarones 1901, Paternal, Ciudad Autonoma de Buenos Aires, Argentina
B30: Bodegon | C30: Bodegon | D30: Brodo Cantina (club Rodrigue Peña) | E30: GBA | F30: Martinez | G30: https://www.instagram.com/p/DP7StRkktcv/ | H30: Pasaje Murillo 2481 | I30: https://www.google.com/maps/search/?api=1&query=Brodo%20Cantina%20%28club%20Rodrigue%20Pe%C3%B1a%29%2C%20Pasaje%20Murillo%202481%2C%20Martinez%2C%20Provincia%20de%20Buenos%20Aires%2C%20Argentina | J30: Pasaje Murillo 2481, Martinez, Provincia de Buenos Aires, Argentina
B31: Bodegon | C31: Bodegon | D31: El Tokio | E31: CABA | F31: Villa Santa Rita | G31: https://www.instagram.com/p/DRZjERQkXk6/ | H31: Av. Alvarez Jonte 3548 | I31: https://www.google.com/maps/search/?api=1&query=El%20Tokio%2C%20Av.%20Alvarez%20Jonte%203548%2C%20Villa%20Santa%20Rita%2C%20CABA%2C%20Argentina | J31: Av. Alvarez Jonte 3548, Villa Santa Rita, Ciudad Autonoma de Buenos Aires, Argentina
B32: Bodegon | C32: Bodegon | D32: Cantina Sanabria | E32: CABA | F32: Devoto | G32: https://www.instagram.com/p/DQhCcdykZqx/ | H32: Sanabria 4589 | I32: https://www.google.com/maps/search/?api=1&query=Cantina%20Sanabria%2C%20Sanabria%204589%2C%20Devoto%2C%20CABA%2C%20Argentina | J32: Sanabria 4589, Devoto, Ciudad Autonoma de Buenos Aires, Argentina
B33: Bodegon | C33: Bodegon | D33: Babieca | E33: CABA | F33: Centro | G33: https://www.instagram.com/p/DQF6AvUEn5N/ | H33: Av. Santa Fe 1898 | I33: https://www.google.com/maps/search/?api=1&query=Babieca%2C%20Av.%20Santa%20Fe%201898%2C%20Centro%2C%20CABA%2C%20Argentina | J33: Av. Santa Fe 1898, Centro, Ciudad Autonoma de Buenos Aires, Argentina
B34: Bodegon | C34: Bodegon | D34: Buona Mangiata | E34: CABA | F34: Villa Crespo | G34: https://www.instagram.com/p/DPM0cxRAXGA/ | H34: Av. Scalabrini Ortiz 802 | I34: https://www.google.com/maps/search/?api=1&query=Buona%20Mangiata%2C%20Av.%20Scalabrini%20Ortiz%20802%2C%20Villa%20Crespo%2C%20CABA%2C%20Argentina | J34: Av. Scalabrini Ortiz 802, Villa Crespo, Ciudad Autonoma de Buenos Aires, Argentina
B35: Bodegon | C35: Bodegon | D35: Viejo Norton | E35: GBA | F35: Vicente Lopez | G35: https://www.instagram.com/p/DPzkFnTEbGl/ | H35: Miguel de Azcuenaga 900 | I35: https://www.google.com/maps/search/?api=1&query=Viejo%20Norton%2C%20Miguel%20de%20Azcuenaga%20900%2C%20Vicente%20Lopez%2C%20Provincia%20de%20Buenos%20Aires%2C%20Argentina | J35: Miguel de Azcuenaga 900, Vicente Lopez, Provincia de Buenos Aires, Argentina
B36: Bodegon | C36: Bodegon | D36: Lo de Bette | E36: CABA | F36: Palermo | G36: https://www.instagram.com/p/DOjpj0jkpw0/ | H36: Uriarte 1602 | I36: https://www.google.com/maps/search/?api=1&query=Lo%20de%20Bette%2C%20Uriarte%201602%2C%20Palermo%2C%20CABA%2C%20Argentina | J36: Uriarte 1602, Palermo, Ciudad Autonoma de Buenos Aires, Argentina
B37: Bodegon | C37: Bodegon | D37: Fraga Bodegon | E37: CABA | F37: Chacarita | G37: https://www.instagram.com/p/DOzKQDqjnI-/ | H37: Av. Dorrego 1194 | I37: https://www.google.com/maps/search/?api=1&query=Fraga%20Bodegon%2C%20Av.%20Dorrego%201194%2C%20Chacarita%2C%20CABA%2C%20Argentina | J37: Av. Dorrego 1194, Chacarita, Ciudad Autonoma de Buenos Aires, Argentina
B38: Bodegon | C38: Bodegon | D38: Bar La Querencia | E38: CABA | F38: Belgrano | G38: https://www.instagram.com/p/DOQ3qFnjeUc/ | H38: Palpa 2383 | I38: https://www.google.com/maps/search/?api=1&query=Bar%20La%20Querencia%2C%20Palpa%202383%2C%20Belgrano%2C%20CABA%2C%20Argentina | J38: Palpa 2383, Belgrano, Ciudad Autonoma de Buenos Aires, Argentina
B39: Bodegon | C39: Bodegon | D39: La Cantina del Gato | E39: GBA | F39: Vicente Lopez | G39: https://www.instagram.com/p/DMJR7l-yLjm/ | H39: Av. Avalos 4205 | I39: https://www.google.com/maps/search/?api=1&query=La%20Cantina%20del%20Gato%2C%20Av.%20Avalos%204205%2C%20Vicente%20Lopez%2C%20Provincia%20de%20Buenos%20Aires%2C%20Argentina | J39: Av. Avalos 4205, Vicente Lopez, Provincia de Buenos Aires, Argentina
B40: Bodegon | C40: Bodegon | D40: La Sarita | E40: GBA | F40: Florida | G40: https://www.instagram.com/p/DNMUmVdOdRQ/ | H40: España 506 | I40: https://www.google.com/maps/search/?api=1&query=La%20Sarita%2C%20Espa%C3%B1a%20506%2C%20Florida%2C%20Provincia%20de%20Buenos%20Aires%2C%20Argentina | J40: España 506, Florida, Provincia de Buenos Aires, Argentina
... B49: Bodegon | C49: Bodegon | D49: Club Montañez | E49: CABA | F49: Colegiales | G49: https://www.instagram.com/p/CtFdjgkux4S/ | H49: Jorge Newbery 1828 | I49: https://www.google.com/maps/search/?api=1&query=Club%20Monta%C3%B1ez%2C%20Jorge%20Newbery%201828%2C%20Colegiales%2C%20CABA%2C%20Argentina | J49: Jorge Newbery 1828, Colegiales, Ciudad Autonoma de Buenos Aires, Argentina
B50: Bodegon | C50: Bodegon | D50: 1810 | E50: CABA | F50: Belgrano | G50: https://www.instagram.com/p/CsmxixBNmkx/ | H50: Mendeza 2320 | I50: https://www.google.com/maps/search/?api=1&query=1810%2C%20Mendeza%202320%2C%20Belgrano%2C%20CABA%2C%20Argentina | J50: Mendeza 2320, Belgrano, Ciudad Autonoma de Buenos Aires, Argentina
B51: Bodegon | C51: Bodegon | D51: La Ochavita | E51: CABA | F51: Mataderos | G51: https://www.instagram.com/p/DFknojZOTy2/ | H51: Pieres 1399 | I51: https://www.google.com/maps/search/?api=1&query=La%20Ochavita%2C%20Pieres%201399%2C%20Mataderos%2C%20CABA%2C%20Argentina | J51: Pieres 1399, Mataderos, Ciudad Autonoma de Buenos Aires, Argentina
...

Sheet Hoja2
B10: Nombre | C10: Direccion | D10: Link Mapa | E10: Video | F10: Visitada | G10: Comentarios
B11: 1810 | C11: Mendeza 2320 | D11: https://www.google.com/maps/search/?api=1&query=1810%2C%20Mendeza%202320%2C%20Belgrano%2C%20CABA%2C%20Argentina | E11: https://www.instagram.com/p/CsmxixBNmkx/ | F11: (en blanco) | G11: (en blanco)
B12: 29Noventa | C12: Echeverria 2990 | D12: https://www.google.com/maps/search/?api=1&query=29Noventa%2C%20Echeverria%202990%2C%20Belgrano%2C%20CABA%2C%20Argentina | E12: https://www.instagram.com/p/C6meb8mPiAY/ | F12: (en blanco) | G12: (en blanco)
B13: 8 esquinas | C13: Av. Forest 1186 | D13: https://www.google.com/maps/search/?api=1&query=8%20esquinas%2C%20Av.%20Forest%201186%2C%20Villa%20Ortuzar%2C%20CABA%2C%20Argentina | E13: https://www.instagram.com/p/C6e1rQ_O7Kb/ | F13: (en blanco) | G13: (en blanco)
B14: A Raja Cincha | C14: Cuenca 1299 | D14: https://www.google.com/maps/search/?api=1&query=A%20Raja%20Cincha%2C%20Cuenca%201299%2C%20Floresta%2C%20CABA%2C%20Argentina | E14: https://www.instagram.com/p/CgAiKAJAeyL/ | F14: (en blanco) | G14: (en blanco)
B15: Abuela 22 | C15: Darregueyra 2218 | D15: https://www.google.com/maps/search/?api=1&query=Abuela%2022%2C%20Darregueyra%202218%2C%20Palermo%2C%20CABA%2C%20Argentina | E15: https://www.instagram.com/p/DDF8yCPhth_/ | F15: (en blanco) | G15: (en blanco)
B16: Adelmo | C16: Av. Dardo Rocha 1734 | D16: https://www.google.com/maps/search/?api=1&query=Adelmo%2C%20Av.%20Dardo%20Rocha%201734%2C%20San%20Isidro%2C%20Provincia%20de%20Buenos%20Aires%2C%20Argentina | E16: https://www.instagram.com/p/DBFK6KqOkBE/ | F16: (en blanco) | G16: (en blanco)
B17: Ahora | C17: Nuñez 3802 | D17: https://www.google.com/maps/search/?api=1&query=Ahora%2C%20Nu%C3%B1ez%203802%2C%20Nu%C3%B1ez%2C%20CABA%2C%20Argentina | E17: https://www.instagram.com/p/DC2i9iaJvUp/ | F17: (en blanco) | G17: (en blanco)
B18: Albamonte | C18: Av. Corrientes 6735 | D18: https://www.google.com/maps/search/?api=1&query=Albamonte%2C%20Av.%20Corrientes%206735%2C%20Chacarita%2C%20CABA%2C%20Argentina | E18: https://www.instagram.com/p/Cd6tAFPlA4h/ | F18: (en blanco) | G18: (en blanco)
B19: Artigas | C19: Gral. Jose Gervasio Artigas 5800 | D19: https://www.google.com/maps/search/?api=1&query=Artigas%2C%20Gral.%20Jose%20Gervasio%20Artigas%205800%2C%20Villa%20Pueyrredon%2C%20CABA%2C%20Argentina | E19: https://www.instagram.com/p/DNLOsypOf3D/ | F19: (en blanco) | G19: (en blanco)
B20: Austria | C20: Roque Saenz Peña 1138 | D20: https://www.google.com/maps/search/?api=1&query=Austria%2C%20Roque%20Saenz%20Pe%C3%B1a%201138%2C%20San%20Isidro%2C%20Provincia%20de%20Buenos%20Aires%2C%20Argentina | E20: https://www.instagram.com/p/ClSAGscJp_T/ | F20: (en blanco) | G20: (en blanco)
B21: Babieca | C21: Av. Santa Fe 1898 | D21: https://www.google.com/maps/search/?api=1&query=Babieca%2C%20Av.%20Santa%20Fe%201898%2C%20Centro%2C%20CABA%2C%20Argentina | E21: https://www.instagram.com/p/DQF6AvUEn5N/ | F21: (en blanco) | G21: (en blanco)
B22: Bar La Querencia | C22: Palpa 2383 | D22: https://www.google.com/maps/search/?api=1&query=Bar%20La%20Querencia%2C%20Palpa%202383%2C%20Belgrano%2C%20CABA%2C%20Argentina | E22: https://www.instagram.com/p/DOQ3qFnjeUc/ | F22: (en blanco) | G22: (en blanco)
B23: Barcelona Asturias | C23: Av. Cordoba 5899 | D23: https://www.google.com/maps/search/?api=1&query=Barcelona%20Asturias%2C%20Av.%20Cordoba%205899%2C%20Palermo%2C%20CABA%2C%20Argentina | E23: https://www.instagram.com/p/C9ySIF-tqjz/ | F23: (en blanco) | G23: (en blanco)
... B119: Viejo Norton | C119: Miguel de Azcuenaga 900 | D119: https://www.google.com/maps/search/?api=1&query=Viejo%20Norton%2C%20Miguel%20de%20Azcuenaga%20900%2C%20Vicente%20Lopez%2C%20Provincia%20de%20Buenos%20Aires%2C%20Argentina | E119: https://www.instagram.com/p/DPzkFnTEbGl/ | F119: (en blanco) | G119: (en blanco)

Sheet Referencia
A1: Localidades GBA / Prov. de Buenos Aires
A2: Tigre
A3: Vicente Lopez
A4: Martinez
A5: San Isidro
A6: Florida
A7: Olivos
A8: Pilar
A9: Quilmes
A10: San Martin
A11: Diego Gaynor
A12: Lanus
A13: La Lucula

Sheet Mapa
A1: Nombre | B1: Categoria | C1: Barrio | D1: Direccion completa | E1: Link Mapa | F1: Video | H1: Cómo ver los 109 puntos en un mapa
A2: =Hoja1!D3 -> Casa Cuba | B2: =Hoja1!B3 -> Bodegon | C2: =Hoja1!F3 -> Belgrano | D2: =Hoja1!J3 -> Cuba 1877, Belgrano, Ciudad Autonoma de Buenos Aires, Argentina | E2: https://www.google.com/maps/search/?api=1&query=Casa%20Cuba%2C%20Cuba%201877%2C%20Belgrano%2C%20CABA%2C%20Argentina | F2: https://www.instagram.com/p/Dcrl0znt4_u/ | H2: OPCIÓN A — Mapa 3D de Excel (interactivo, dentro de Excel)
A3: =Hoja1!D4 -> Burdo | B3: =Hoja1!B4 -> Bodegon | C3: =Hoja1!F4 -> Colegiales | D3: =Hoja1!J4 -> Delgado 1199, Colegiales, Ciudad Autonoma de Buenos Aires, Argentina | E3: https://www.google.com/maps/search/?api=1&query=Burdo%2C%20Delgado%201199%2C%20Colegiales%2C%20CABA%2C%20Argentina | F3: https://www.instagram.com/p/DccKNw2OHoY/ | H3: 1) Hacé clic en cualquier celda de la tabla 'Lugares'. 2) Insertar → Mapa 3D → Abrir Mapas 3D. 3) En Ubicación elegí 'Direccion completa' y marcala como 'Dirección completa'. 4) Categoría → 'Categoria' o 'Barrio' para colorear los pines.
A4: =Hoja1!D5 -> La Escuela | B4: =Hoja1!B5 -> Bodegon | C4: =Hoja1!F5 -> Saavedra | D4: =Hoja1!J5 -> Manuela Pedraza 2803, Saavedra, Ciudad Autonoma de Buenos Aires, Argentina | E4: https://www.google.com/maps/search/?api=1&query=La%20Escuela%2C%20Manuela%20Pedraza%202803%2C%20Saavedra%2C%20CABA%2C%20Argentina | F4: https://www.instagram.com/p/DcJLAs7NTN7/ | H4: OPCIÓN B — Google My Maps (interactivo, se comparte por celular)
A5: =Hoja1!D6 -> Cantina Mandia | B5: =Hoja1!B6 -> Bodegon | C5: =Hoja1!F6 -> Colegiales | D5: =Hoja1!J6 -> Zapiola 1218, Colegiales, Ciudad Autonoma de Buenos Aires, Argentina | E5: https://www.google.com/maps/search/?api=1&query=Cantina%20Mandia%2C%20Zapiola%201218%2C%20Colegiales%2C%20CABA%2C%20Argentina | F5: https://www.instagram.com/p/DcCPkO3TdK4/ | H5: 1) Entrá a mymaps.google.com → Crear un mapa nuevo. 2) Importar → subí este archivo (o copiá A1:F110 a un CSV). 3) Columna de posición: 'Direccion completa'. 4) Título de los marcadores: 'Nombre'. Los links de Maps y de Instagram quedan en la ficha de cada punto.
A6: =Hoja1!D7 -> Somos Asado | B6: =Hoja1!B7 -> Bodegon | C6: =Hoja1!F7 -> Villa Crespo | D6: =Hoja1!J7 -> Av. Scalabrini Ortiz 651, Villa Crespo, Ciudad Autonoma de Buenos Aires, Argentina | E6: https://www.google.com/maps/search/?api=1&query=Somos%20Asado%2C%20Av.%20Scalabrini%20Ortiz%20651%2C%20Villa%20Crespo%2C%20CABA%2C%20Argentina | F6: https://www.instagram.com/p/Db_vglEp-xj/ | H6: Nota: las columnas A a D son fórmulas que se actualizan solas desde Hoja1. Las columnas E y F son texto fijo copiado de Hoja1 (Excel no permite hipervínculos clickeables sobre una fórmula).
A7: =Hoja1!D8 -> Laserio Cantina | B7: =Hoja1!B8 -> Bodegon | C7: =Hoja1!F8 -> Devoto | D7: =Hoja1!J8 -> Mosconi 3906, Devoto, Ciudad Autonoma de Buenos Aires, Argentina | E7: https://www.google.com/maps/search/?api=1&query=Laserio%20Cantina%2C%20Mosconi%203906%2C%20Devoto%2C%20CABA%2C%20Argentina | F7: https://www.instagram.com/p/DbrOs5xOxDc/
A8: =Hoja1!D9 -> Tinte Atelier de pasta | B8: =Hoja1!B9 -> Bodegon | C8: =Hoja1!F9 -> Villa Crespo | D8: =Hoja1!J9 -> Castillo 997, Villa Crespo, Ciudad Autonoma de Buenos Aires, Argentina | E8: https://www.google.com/maps/search/?api=1&query=Tinte%20Atelier%20de%20pasta%2C%20Castillo%20997%2C%20Villa%20Crespo%2C%20CABA%2C%20Argentina | F8: https://www.instagram.com/p/DatqytBxIVR/
A9: =Hoja1!D10 -> Rioba | B9: =Hoja1!B10 -> Bodegon | C9: =Hoja1!F10 -> Palermo | D9: =Hoja1!J10 -> Costa Rica 4588, Palermo, Ciudad Autonoma de Buenos Aires, Argentina | E9: https://www.google.com/maps/search/?api=1&query=Rioba%2C%20Costa%20Rica%204588%2C%20Palermo%2C%20CABA%2C%20Argentina | F9: https://www.instagram.com/p/DaRWCBzRStd/
A10: =Hoja1!D11 -> Ovidio | B10: =Hoja1!B11 -> Bodegon | C10: =Hoja1!F11 -> Belgrano | D10: =Hoja1!J11 -> Jose Hernandez 2345, Belgrano, Ciudad Autonoma de Buenos Aires, Argentina | E10: https://www.google.com/maps/search/?api=1&query=Ovidio%2C%20Jose%20Hernandez%202345%2C%20Belgrano%2C%20CABA%2C%20Argentina | F10: https://www.instagram.com/p/DYnaFAQPTBO/
A11: =Hoja1!D12 -> Rondinella | B11: =Hoja1!B12 -> Bodegon | C11: =Hoja1!F12 -> Chacarita | D11: =Hoja1!J12 -> Av. Alvarez thomas 12, Chacarita, Ciudad Autonoma de Buenos Aires, Argentina | E11: https://www.google.com/maps/search/?api=1&query=Rondinella%2C%20Av.%20Alvarez%20thomas%2012%2C%20Chacarita%2C%20CABA%2C%20Argentina | F11: https://www.instagram.com/p/DGLib_9Rou4/
A12: =Hoja1!D13 -> GEVP | B12: =Hoja1!B13 -> Bodegon | C12: =Hoja1!F13 -> Villa del Parque | D12: =Hoja1!J13 -> Tinogaste 3455, Villa del Parque, Ciudad Autonoma de Buenos Aires, Argentina | E12: https://www.google.com/maps/search/?api=1&query=GEVP%2C%20Tinogaste%203455%2C%20Villa%20del%20Parque%2C%20CABA%2C%20Argentina | F12: https://www.instagram.com/reel/DTStg6GjYtH/
A13: =Hoja1!D14 -> La Tia Ñata | B13: =Hoja1!B14 -> Bodegon | C13: =Hoja1!F14 -> Tigre | D13: =Hoja1!J14 -> Las Heras 1318, Dique Lujan, Tigre, Provincia de Buenos Aires, Argentina | E13: https://www.google.com/maps/search/?api=1&query=La%20Tia%20%C3%91ata%2C%20Las%20Heras%201318%2C%20Dique%20Lujan%2C%20Tigre%2C%20Provincia%20de%20Buenos%20Aires%2C%20Argentina | F13: https://www.instagram.com/p/DYKu3q0T0Rj/
A14: =Hoja1!D15 -> La Despensa de Aurora | B14: =Hoja1!B15 -> Bodegon | C14: =Hoja1!F15 -> Devoto | D14: =Hoja1!J15 -> Griveo 3501, Devoto, Ciudad Autonoma de Buenos Aires, Argentina | E14: https://www.google.com/maps/search/?api=1&query=La%20Despensa%20de%20Aurora%2C%20Griveo%203501%2C%20Devoto%2C%20CABA%2C%20Argentina | F14: https://www.instagram.com/p/DYF-3OkRmVN/
A15: =Hoja1!D16 -> Lo de Fito | B15: =Hoja1!B16 -> Bodegon | C15: =Hoja1!F16 -> Devoto | D15: =Hoja1!J16 -> Mercedes 4280, Devoto, Ciudad Autonoma de Buenos Aires, Argentina | E15: https://www.google.com/maps/search/?api=1&query=Lo%20de%20Fito%2C%20Mercedes%204280%2C%20Devoto%2C%20CABA%2C%20Argentina | F15: https://www.instagram.com/p/DXfhmHpDY3m/
A16: =Hoja1!D17 -> The New Brighton | B16: =Hoja1!B17 -> Bodegon | C16: =Hoja1!F17 -> Retiro | D16: =Hoja1!J17 -> Sarmiento 645, Retiro, Ciudad Autonoma de Buenos Aires, Argentina | E16: https://www.google.com/maps/search/?api=1&query=The%20New%20Brighton%2C%20Sarmiento%20645%2C%20Retiro%2C%20CABA%2C%20Argentina | F16: https://www.instagram.com/p/DWXIT32xDqx/
A17: =Hoja1!D18 -> Lalin | B17: =Hoja1!B18 -> Bodegon | C17: =Hoja1!F18 -> Monserrat | D17: =Hoja1!J18 -> Moreno 1949, Monserrat, Ciudad Autonoma de Buenos Aires, Argentina | E17: https://www.google.com/maps/search/?api=1&query=Lalin%2C%20Moreno%201949%2C%20Monserrat%2C%20CABA%2C%20Argentina | F17: https://www.instagram.com/p/DWVAqVoRcgP/
A18: =Hoja1!D19 -> Casa Albardon | B18: =Hoja1!B19 -> Bodegon | C18: =Hoja1!F19 -> Tigre | D18: =Hoja1!J19 -> Luis Pereyra 2, Tigre, Provincia de Buenos Aires, Argentina | E18: https://www.google.com/maps/search/?api=1&query=Casa%20Albardon%2C%20Luis%20Pereyra%202%2C%20Tigre%2C%20Provincia%20de%20Buenos%20Aires%2C%20Argentina | F18: https://www.instagram.com/p/DV3sSQijbB6/
... A110: =Hoja1!D111 -> 29Noventa | B110: =Hoja1!B111 -> Bodegon | C110: =Hoja1!F111 -> Belgrano | D110: =Hoja1!J111 -> Echeverria 2990, Belgrano, Ciudad Autonoma de Buenos Aires, Argentina | E110: https://www.google.com/maps/search/?api=1&query=29Noventa%2C%20Echeverria%202990%2C%20Belgrano%2C%20CABA%2C%20Argentina | F110: https://www.instagram.com/p/C6meb8mPiAY/
